<robot
  name="Robot2URDF">

  <material name="Black">
    <color rgba="0.0 0.0 0.0 1.0"/>
  </material>
  <material name="Red">
    <color rgba="0.8 0.0 0.0 1.0"/>
  </material>
  <material name="White">
    <color rgba="1.0 1.0 1.0 1.0"/>
  </material>
  <material name="Blue">
    <color rgba="0.0 0.0 0.8 1.0"/>
  </material>


<link name="world">
    <visual>
      <geometry>
        <box size="0.00 0.05 0.06" />
      </geometry>
      <material name="Green" />
    </visual>
    <inertial>
      <mass value="0.000001" />
      <origin xyz="0 0 0" />
      <inertia ixx="0.0001" ixy="0.0" ixz="0.0"
        iyy="0.0001" iyz="0.0"
        izz="0.0001" />
    </inertial>
  </link>

  <joint name="world_joint" type="fixed">
    <origin xyz="0 0 0" rpy="0 0 0 " />
    <parent link="world" />
    <child link="map" />
  </joint>

  <link name="map">
    <visual>
      <geometry>
        <box size="0.00 0.05 0.06" />
      </geometry>
      <material name="Green" />
    </visual>
    <inertial>
      <mass value="0.000001" />
      <origin xyz="0 0 0" />
      <inertia ixx="0.0001" ixy="0.0" ixz="0.0"
        iyy="0.0001" iyz="0.0"
        izz="0.0001" />
    </inertial>
  </link>

  <joint name="map_joint" type="fixed">
    <origin xyz="0 0 0" rpy="0 0 0 " />
    <parent link="map" />
    <child link="odom" />
  </joint>

  <link name="odom">
    <visual>
      <geometry>
        <box size="0.00 0.05 0.06" />
      </geometry>
      <material name="Green" />
    </visual>
    <inertial>
      <mass value="0.000001" />
      <origin xyz="0 0 0" />
      <inertia ixx="0.0001" ixy="0.0" ixz="0.0"
        iyy="0.0001" iyz="0.0"
        izz="0.0001" />
    </inertial>
  </link>

  <joint name="odom_joint" type="fixed">
    <origin xyz="0 0 0" rpy="0 0 0 " />
    <parent link="odom" />
    <child link="base_footprint" />
  </joint>

    <link name="base_footprint">
    <visual>
      <geometry>
        <box size="0.00 0.05 0.06" />
      </geometry>
      <material name="Green" />
    </visual>
    <inertial>
      <mass value="0.000001" />
      <origin xyz="0 0 0" />
      <inertia ixx="0.0001" ixy="0.0" ixz="0.0"
        iyy="0.0001" iyz="0.0"
        izz="0.0001" />
    </inertial>
  </link>

  <joint name="base_footprint_joint" type="fixed">
    <origin xyz="0 0 0" rpy="0 0 0"/>
    <parent link="base_footprint" />
    <child link="base_link" />
  </joint>

  <link
    name="base_link">
    <inertial>
      <origin
        xyz="-2.09921310855692E-06 0.0066269156198499 0.159301835175294"
        rpy="0 0 0" />
      <mass
        value="4" />
      <inertia
        ixx="0.0870045613159956"
        ixy="8.3173092641959E-07"
        ixz="1.02743450443904E-06"
        iyy="0.0996825873015556"
        iyz="0.000494011430521007"
        izz="0.0289836066026514" />
    </inertial>
    <visual>
      <origin
        xyz="0 0 0"
        rpy="0 0 1.570796327" />
      <geometry>
        <mesh
          filename="package://Robot2URDF/meshes/base_link.STL" />
      </geometry>
      <material
        name="">
        <color
          rgba="0.0 0.0 0.0 1" />
      </material>
    </visual>
    <collision>
      <origin
        xyz="0 0 0"
        rpy="0 0 0" />
      <geometry>
        <mesh
          filename="package://Robot2URDF/meshes/base_link.STL" />
      </geometry>
    </collision>

  </link>

  <link
    name="right_wheel_link">
    <inertial>
      <origin
        xyz="0.0344807432762186 3.03576608295941E-17 1.73472347597681E-18"
        rpy="0 0 0" />
      <mass
        value="0.480959803694537" />
      <inertia
        ixx="0.00102"
        ixy="0"
        ixz="0"
        iyy="0.00102"
        iyz="0"
        izz="0.002" />
    </inertial>
    <visual>
      <origin
        xyz="-0.13 0.15 -0.01"
        rpy="0 0.2 1.570796" />
      <geometry>
        <mesh
          filename="package://Robot2URDF/meshes/right_wheel_link.STL" />
      </geometry>
      <material
        name="">
        <color
          rgba="0.4 0.4 0.4 1" />
      </material>
    </visual>
    <collision>
      <origin
        xyz="0 0 0"
        rpy="0 0 0" />
      <geometry>
        <mesh
          filename="package://Robot2URDF/meshes/right_wheel_link.STL" />
      </geometry>
    </collision>
  </link>

  <gazebo reference="right_wheel_link">
    <mu1 value="1.0"/>
    <mu2 value="1.0"/>
    <kp value="10000000.0"/>
    <kd value="1.0"/>
    <fdir1 value="1 0 0"/>
    <material>Gazebo/Black</material>
    <turnGravityOff>false</turnGravityOff>
  </gazebo>

  <joint
    name="right_wheel_joint"
    type="continuous">
    <origin
      xyz="-0.13568 0 -0.011525"
      rpy="0.21804 1.6535E-16 -3.1416" />
    <parent
      link="base_link" />
    <child
      link="right_wheel_link" />
    <axis
      xyz="-1 0 0" />
  </joint>

  <transmission name="right_wheel_joint_trans">
    <type>transmission_interface/SimpleTransmission</type>
    <joint name="right_wheel_joint"/>
    <actuator name="right_wheel_joint_motor">
      <hardwareInterface>EffortJointInterface</hardwareInterface>
      <mechanicalReduction>1</mechanicalReduction>
    </actuator>
  </transmission>

  <link
    name="left_wheel_link">
    <inertial>
      <origin
        xyz="0.0344807432762186 3.12250225675825E-17 3.72965547335014E-17"
        rpy="0 0 0" />
      <mass
        value="0.480959803694537" />
      <inertia
        ixx="0.0012"
        ixy="0"
        ixz="0"
        iyy="0.0012"
        iyz="0"
        izz="0.002" />
    </inertial>
    <visual>
      <origin
        xyz="-0.14 -0.09 -0.13"
        rpy="0 0.9 -1.571" />
      <geometry>
        <mesh
          filename="package://Robot2URDF/meshes/left_wheel_link.STL" />
      </geometry>
      <material
        name="">
        <color
          rgba="0.4 0.4 0.4 1" />
      </material>
    </visual>
    <collision>
      <origin
        xyz="0 0 0"
        rpy="0 0 0" />
      <geometry>
        <mesh
          filename="package://Robot2URDF/meshes/left_wheel_link.STL" />
      </geometry>
    </collision>
  </link>

  <gazebo reference="left_wheel_link">
    <mu1 value="1.0"/>
    <mu2 value="1.0"/>
    <kp value="10000000.0"/>
    <kd value="1.0"/>
    <fdir1 value="1 0 0"/>
    <material>Gazebo/Black</material>
    <turnGravityOff>false</turnGravityOff>
  </gazebo>

  <joint
    name="left_wheel_joint"
    type="continuous">
    <origin
      xyz="0.13568 0 -0.011525"
      rpy="2.296 0 0" />
    <parent
      link="base_link" />
    <child
      link="left_wheel_link" />
    <axis
      xyz="1 0 0" />
  </joint>

  <transmission name="left_wheel_joint_trans">
    <type>transmission_interface/SimpleTransmission</type>
    <joint name="left_wheel_joint"/>
    <actuator name="left_wheel_joint_motor">
      <hardwareInterface>EffortJointInterface</hardwareInterface>
      <mechanicalReduction>1</mechanicalReduction>
    </actuator>
  </transmission>

  <link
    name="front_caster_link">
    <inertial>
      <origin
        xyz="-0.0111817670045408 0.0146095902446174 1.1444300757649E-05"
        rpy="0 0 0" />
      <mass
        value="0.0829222708781185" />
      <inertia
        ixx="0.001"
        ixy="0"
        ixz="0"
        iyy="0.001"
        iyz="0"
        izz="0.001" />
    </inertial>
    <visual>
      <origin
        xyz="0.16 0 -0.16"
        rpy="0 0 0" />
      <geometry>
        <mesh
          filename="package://Robot2URDF/meshes/front_caster_link.STL" />
      </geometry>
      <material
        name="">
        <color
          rgba="0.2 0.2 0.2 1" />
      </material>
    </visual>
    <collision>
      <origin
        xyz="0 0 0"
        rpy="0 0 0" />
      <geometry>
        <mesh
          filename="package://Robot2URDF/meshes/front_caster_link.STL" />
      </geometry>
    </collision>
  </link>

  <gazebo reference="front_caster_link">
    <turnGravityOff>false</turnGravityOff>
  </gazebo>

  <joint
    name="front_caster_joint"
    type="fixed">
    <origin
      xyz="6.5739E-05 -0.15813 -0.0333"
      rpy="-1.5708 6.123E-17 1.5708" />
    <parent
      link="base_link" />
    <child
      link="front_caster_link" />
    <axis
      xyz="0 0 0" />
  </joint>


  <link
    name="back_caster_link">
    <inertial>
      <origin
        xyz="-0.0111817670045407 -0.0146095902446174 -1.1444300757631E-05"
        rpy="0 0 0" />
      <mass
        value="0.0829222708781185" />
      <inertia
        ixx="0.001"
        ixy="0"
        ixz="0"
        iyy="0.001"
        iyz="0"
        izz="0.001" />
    </inertial>
    <visual>
      <origin
        xyz="0.15 0 0.16"
        rpy="0 0 0" />
      <geometry>
        <mesh
          filename="package://Robot2URDF/meshes/back_caster_link.STL" />
      </geometry>
      <material
        name="">
        <color
          rgba="0.2 0.2 0.2 1" />
      </material>
    </visual>
    <collision>
      <origin
        xyz="0 0 0"
        rpy="0 0 0" />
      <geometry>
        <mesh
          filename="package://Robot2URDF/meshes/back_caster_link.STL" />
      </geometry>
    </collision>
  </link>

  <gazebo reference="back_caster_link">
    <turnGravityOff>false</turnGravityOff>
  </gazebo>

  <joint
    name="back_caster_joint"
    type="fixed">
    <origin
      xyz="-6.5739E-05 0.154 -0.0333"
      rpy="1.5708 -6.123E-17 -1.5708" />
    <parent
      link="base_link" />
    <child
      link="back_caster_link" />
    <axis
      xyz="0 0 0" />
  </joint>
  <link
    name="sensor_kinect_link">
    <inertial>
      <origin
        xyz="4.6571422463929E-05 -0.00661622471020076 -0.0295600291595772"
        rpy="0 0 0" />
      <mass
        value="0.05" />
      <inertia
        ixx="0.0001"
        ixy="0"
        ixz="0"
        iyy="0.0001"
        iyz="0"
        izz="0.0001" />
    </inertial>
    <visual>
      <origin
        xyz="0.15 0 -0.1"
        rpy="0.15 1.5 0.18" />
      <geometry>
        <mesh
          filename="package://Robot2URDF/meshes/sensor_kinect_link.STL" />
      </geometry>
      <material
        name="">
        <color
          rgba="0.5 0.5 0.9 1" />
      </material>
    </visual>
    <collision>
      <origin
        xyz="0 0 0"
        rpy="0 0 0" />
      <geometry>
        <mesh
          filename="package://Robot2URDF/meshes/sensor_kinect_link.STL" />
      </geometry>
    </collision>
  </link>
  <joint
    name="sensor_kinect_joint"
    type="fixed">
    <origin
      xyz="0 -0.124593228242069 0.059501311027021"
      rpy="1.50898907863485 0 0" />
    <parent
      link="base_link" />
    <child
      link="sensor_kinect_link" />
    <axis
      xyz="0 0 0" />
  </joint>



  <joint name="laser_joint" type="fixed">
    <origin xyz="-0.005 0.00 0.003" rpy="0 0 0" />
    <parent link="base_link" />
    <child link="camera_link" />
  </joint>

  <link name="camera_link">
    <visual>
      <geometry>
        <box size="0.00 0.05 0.06" />
      </geometry>
      <material name="Green" />
    </visual>
    <inertial>
      <mass value="0.000001" />
      <origin xyz="0 0 0" />
      <inertia ixx="0.0001" ixy="0.0" ixz="0.0"
        iyy="0.0001" iyz="0.0"
        izz="0.0001" />
    </inertial>
  </link>


    <joint name="joint1" type="fixed">
    <origin xyz="-0.005 0.00 0.003" rpy="0 0 0 " />
    <parent link="base_link" />
    <child link="/camera_depth_optical_frame" />
  </joint>

  <link name="/camera_depth_optical_frame">
    <visual>
      <geometry>
        <box size="0.00 0.05 0.06" />
      </geometry>
      <material name="Green" />
    </visual>
    <inertial>
      <mass value="0.000001" />
      <origin xyz="0 0 0" />
      <inertia ixx="0.0001" ixy="0.0" ixz="0.0"
        iyy="0.0001" iyz="0.0"
        izz="0.0001" />
    </inertial>
  </link>


    <joint name="joint2" type="fixed">
    <origin xyz="-0.005 0.00 0.003" rpy="0 0 0 " />
    <parent link="base_link" />
    <child link="camera_depth_frame" />
  </joint>

  <link name="camera_depth_frame">
    <visual>
      <geometry>
        <box size="0.00 0.05 0.06" />
      </geometry>
      <material name="Green" />
    </visual>
    <inertial>
      <mass value="0.000001" />
      <origin xyz="0 0 0" />
      <inertia ixx="0.0001" ixy="0.0" ixz="0.0"
        iyy="0.0001" iyz="0.0"
        izz="0.0001" />
    </inertial>
  </link>

    <joint name="joint3" type="fixed">
    <origin xyz="-0.005 0.00 0.003" rpy="0 0 0 " />
    <parent link="base_link" />
    <child link="camera_depth_optical_frame" />
  </joint>

  <link name="camera_depth_optical_frame">
    <visual>
      <geometry>
        <box size="0.00 0.05 0.06" />
      </geometry>
      <material name="Green" />
    </visual>
    <inertial>
      <mass value="0.000001" />
      <origin xyz="0 0 0" />
      <inertia ixx="0.0001" ixy="0.0" ixz="0.0"
        iyy="0.0001" iyz="0.0"
        izz="0.0001" />
    </inertial>
  </link>


<!--camera link-->

</robot>
